ERROR: 2023-09-16 14:39:20,033 | auth.py| func: is_send_otp| line number: 60| While sending OTP to client an exception occur == > ['twilio.base.exceptions.TwilioRestException: \n\x1b[31m\x1b[49mHTTP Error\x1b[0m \x1b[37m\x1b[49mYour request was:\x1b[0m\n\n\x1b[36m\x1b[49mPOST /Accounts/AC74f8aa592b9f4bc82af4402dfd2ce24a/Messages.json\x1b[0m\n\n\x1b[37m\x1b[49mTwilio returned the following information:\x1b[0m\n\n\x1b[34m\x1b[49mUnable to create record: Authenticate\x1b[0m\n\n\x1b[37m\x1b[49mMore information may be available here:\x1b[0m\n\n\x1b[34m\x1b[49mhttps://www.twilio.com/docs/errors/20003\x1b[0m\n\n\n'] 
ERROR: 2023-09-16 15:35:04,830 | auth.py| func: is_send_otp| line number: 60| While sending OTP to client an exception occur == > ['twilio.base.exceptions.TwilioRestException: \n\x1b[31m\x1b[49mHTTP Error\x1b[0m \x1b[37m\x1b[49mYour request was:\x1b[0m\n\n\x1b[36m\x1b[49mPOST /Accounts/AC74f8aa592b9f4bc82af4402dfd2ce24a/Messages.json\x1b[0m\n\n\x1b[37m\x1b[49mTwilio returned the following information:\x1b[0m\n\n\x1b[34m\x1b[49mUnable to create record: Authenticate\x1b[0m\n\n\x1b[37m\x1b[49mMore information may be available here:\x1b[0m\n\n\x1b[34m\x1b[49mhttps://www.twilio.com/docs/errors/20003\x1b[0m\n\n\n'] 
INFO: 2023-09-16 15:37:16,370 | auth_view.py| func: post| line number: 70| OTP Generated Successfully.
INFO: 2023-09-16 15:40:33,911 | auth.py| func: is_send_otp| line number: 56| OTP Sent Successfully.
INFO: 2023-09-16 15:50:17,938 | auth_view.py| func: post| line number: 203| This 7056599221 has locked for next 10 minutes.
INFO: 2023-09-16 16:47:55,360 | auth_view.py| func: post| line number: 158| This 123456 has expired.
INFO: 2023-09-16 17:26:57,601 | auth.py| func: is_send_otp| line number: 56| OTP Sent Successfully.
INFO: 2023-09-16 17:27:28,886 | auth_view.py| func: post| line number: 185| OTP matched successfully and This 7056599221 user has logged in.
